Traceback (most recent call last):
  File "/home/danbot/code/data_analysis/lib/python3.12/site-packages/jupyter_core/utils/__init__.py", line 154, in wrapped
    asyncio.get_running_loop()
RuntimeError: no running event loop

During handling of the above exception, another exception occurred:

Traceback (most recent call last):
  File "/home/danbot/code/data_analysis/lib/python3.12/site-packages/jupyter_cache/executors/utils.py", line 58, in single_nb_execution
    executenb(
  File "/home/danbot/code/data_analysis/lib/python3.12/site-packages/nbclient/client.py", line 1319, in execute
    return NotebookClient(nb=nb, resources=resources, km=km, **kwargs).execute()
           ^^^^^^^^^^^^^^^^^^^^^^^^^^^^^^^^^^^^^^^^^^^^^^^^^^^^^^^^^^^^^^^^^^^^^
  File "/home/danbot/code/data_analysis/lib/python3.12/site-packages/jupyter_core/utils/__init__.py", line 158, in wrapped
    return loop.run_until_complete(inner)
           ^^^^^^^^^^^^^^^^^^^^^^^^^^^^^^
  File "/usr/lib/python3.12/asyncio/base_events.py", line 687, in run_until_complete
    return future.result()
           ^^^^^^^^^^^^^^^
  File "/home/danbot/code/data_analysis/lib/python3.12/site-packages/nbclient/client.py", line 709, in async_execute
    await self.async_execute_cell(
  File "/home/danbot/code/data_analysis/lib/python3.12/site-packages/nbclient/client.py", line 1062, in async_execute_cell
    await self._check_raise_for_error(cell, cell_index, exec_reply)
  File "/home/danbot/code/data_analysis/lib/python3.12/site-packages/nbclient/client.py", line 918, in _check_raise_for_error
    raise CellExecutionError.from_cell_and_msg(cell, exec_reply_content)
nbclient.exceptions.CellExecutionError: An error occurred while executing the following cell:
------------------
import os
import pandas as pd
import numpy as np
import json
from time import time
import xarray as xr
import geopandas as gpd

from scipy.spatial import cKDTree
from sklearn.preprocessing import StandardScaler
from collections import defaultdict

import xgboost as xgb
xgb.config_context(verbosity=2)
from scipy.stats import norm, laplace, genextreme

import jax
import jax.numpy as jnp
from jax import jit

# from KDEpy import FFTKDE

from kde_estimator import KDEEstimator
from fdc_estimator_context import FDCEstimationContext 
from fdc_data import StationData

import data_processing_functions as dpf

from concurrent.futures import ThreadPoolExecutor
from itertools import combinations

from pathlib import Path
BASE_DIR = os.getcwd()
------------------


[31m---------------------------------------------------------------------------[39m
[31mModuleNotFoundError[39m                       Traceback (most recent call last)
[36mCell[39m[36m [39m[32mIn[1][39m[32m, line 23[39m
[32m     19[39m [38;5;28;01mfrom[39;00m[38;5;250m [39m[34;01mjax[39;00m[38;5;250m [39m[38;5;28;01mimport[39;00m jit
[32m     21[39m [38;5;66;03m# from KDEpy import FFTKDE[39;00m
[32m---> [39m[32m23[39m [38;5;28;01mfrom[39;00m[38;5;250m [39m[34;01mkde_estimator[39;00m[38;5;250m [39m[38;5;28;01mimport[39;00m KDEEstimator
[32m     24[39m [38;5;28;01mfrom[39;00m[38;5;250m [39m[34;01mfdc_estimator_context[39;00m[38;5;250m [39m[38;5;28;01mimport[39;00m FDCEstimationContext 
[32m     25[39m [38;5;28;01mfrom[39;00m[38;5;250m [39m[34;01mfdc_data[39;00m[38;5;250m [39m[38;5;28;01mimport[39;00m StationData

[31mModuleNotFoundError[39m: No module named 'kde_estimator'

